<?xml version="1.0"?>

<robot name="fourtwisty">

  <!-- *************************************************** -->
  <!-- ******************** Kinematics ******************* -->
  <!-- *************************************************** -->
  <!-- Note the 'origin' tag in the joints defines the
       shift and reorientation before the continuous joint
       rotates around the 'axis'. -->

  <link name="world"/>

  <joint name="rotate1" type="continuous">
    <parent link="world"/>
    <child  link="link1"/>
    <origin xyz="0 0 0.4" rpy="0 0 0"/>
    <axis   xyz="0 0 1"/>
  </joint>

  <link name="link1"/>

  <joint name="rotate2" type="continuous">
    <parent link="link1"/>
    <child  link="link2"/>
    <origin xyz="0 0.4 0" rpy="1.571 0 3.141"/>
    <axis   xyz="0 0 1"/>
  </joint>

  <link name="link2"/>

  <joint name="rotate3" type="continuous">
    <parent link="link2"/>
    <child  link="link3"/>
    <origin xyz="0 -0.4 0" rpy="1.571 0 0"/>
    <axis   xyz="0 0 1"/>
  </joint>

  <link name="link3"/>

  <joint name="rotate4" type="continuous">
    <parent link="link3"/>
    <child  link="tip"/>
    <origin xyz="0 0.4 0" rpy="-1.571 0 0"/>
    <axis   xyz="0 0 1"/>
  </joint>

  <link name="tip"/>

</robot>

